<?xml version="1.0" ?>
<!-- =================================================================================== -->
<!-- |    This document was autogenerated by xacro from /home/gregoire/DocPartages/Projet/FoodForAll/SimulateurFarmbot/gazebo_simulator/farmbot_catkin_ws/src/farmbot_description/urdf/joints/joint_gantry_crossSlide.xacro | -->
<!-- |    EDITING THIS FILE BY HAND IS NOT RECOMMENDED                                 | -->
<!-- =================================================================================== -->
<robot name="fixes_joints" xmlns:xacro="http://www.ros.org/wiki/xacro">
  <joint name="joint_gantry_crossSlide" type="prismatic">
    <parent link="gantry"/>
    <child link="cross_slide"/>
    <axis xyz="1 0 0"/>
    <limit effort="1000.0" lower="-0.38" upper="0" velocity="0.5"/>
    <origin rpy="0 0 0" xyz="0 0 0"/>
  </joint>
</robot>
