<?xml version="1.0" ?>
<!-- =================================================================================== -->
<!-- |    This document was autogenerated by xacro from /home/gregoire/DocPartages/Projet/FoodForAll/SimulateurFarmbot/gazebo_simulator/farmbot_catkin_ws/src/farmbot_description/urdf/joints/joint_tracks_gantry.xacro | -->
<!-- |    EDITING THIS FILE BY HAND IS NOT RECOMMENDED                                 | -->
<!-- =================================================================================== -->
<robot name="fixes_joints" xmlns:xacro="http://www.ros.org/wiki/xacro">
  <joint name="joint_tracks_gantry" type="prismatic">
    <parent link="tracks"/>
    <child link="gantry"/>
    <axis xyz="0 1 0"/>
    <limit effort="1000.0" lower="-0.38" upper="0" velocity="0.5"/>
    <origin rpy="0 0 1.57079632679" xyz="0 0.745 0.78"/>
  </joint>
  <!--
  <joint name="joint_gantry_cross_slide" type="fixed">
    <parent link="gantry"/>
    <child link="cross_slide"/>
  </joint>
    <joint name="joint_tracks_gantry" type="fixed">
    <parent link="tracks"/>
    <child link="gantry"/>
  </joint>
    <joint name="joint_raised_bed_tracks" type="fixed">
    <parent link="raised_bed"/>
    <child link="tracks"/>
  </joint>
-->
</robot>
