<?xml version="1.0"?>
<robot name="fixes_joints" xmlns:xacro="http://www.ros.org/wiki/xacro">
  <joint name="joint_cross_slide_z_axis" type="prismatic">
    <parent link="cross_slide"/>
    <child link="z_axis"/>
    <axis xyz="0 0 -1"/>
    <limit effort="1000.0" lower="-0.38" upper="0.35" velocity="0.5"/>
    <origin rpy="0 0 0" xyz="0 0 0"/>
  </joint>
  <!--
  <joint name="joint_gantry_cross_slide" type="fixed">
    <parent link="gantry"/>
    <child link="cross_slide"/>
  </joint>
    <joint name="joint_tracks_gantry" type="fixed">
    <parent link="tracks"/>
    <child link="gantry"/>
  </joint>
    <joint name="joint_raised_bed_tracks" type="fixed">
    <parent link="raised_bed"/>
    <child link="tracks"/>
  </joint>
-->
</robot>
