<?xml version="1.0" ?>
<!-- =================================================================================== -->
<!-- |    This document was autogenerated by xacro from assembly.xacro                 | -->
<!-- |    EDITING THIS FILE BY HAND IS NOT RECOMMENDED                                 | -->
<!-- =================================================================================== -->
<robot name="farmbot" xmlns:xacro="http://www.ros.org/wiki/xacro">
  <link name="z_axis">
    <visual>
      <geometry>
        <mesh filename="package://farmbot_description/meshes/visual/z_axis.dae"/>
      </geometry>
    </visual>
    <collision>
      <geometry>
        <mesh filename="package://farmbot_description/meshes/collision/collision_zAxis.stl"/>
      </geometry>
    </collision>
    <inertial>
      <mass value="10"/>
      <inertia ixx="0.1" ixy="0.0" ixz="0.0" iyy="0.1" iyz="0.0" izz="0.1"/>
    </inertial>
  </link>
  
s
  <link name="cross_slide">
    <visual>
      <geometry>
        <mesh filename="package://farmbot_description/meshes/visual/cross_slide.dae"/>
      </geometry>
    </visual>
    <collision>
      <geometry>
        <mesh filename="package://farmbot_description/meshes/visual/cross_slide.dae"/>
      </geometry>
    </collision>
    <inertial>
      <mass value="1"/>
      <inertia ixx="0.1" ixy="0.0" ixz="0.0" iyy="0.1" iyz="0.0" izz="0.1"/>
    </inertial>
  </link>
  <link name="raised_bed">
    <visual>
      <geometry>
        <mesh filename="package://farmbot_description/meshes/visual/raised_bed.dae"/>
      </geometry>
    </visual>
    <collision>
      <geometry>
        <box size="1 1 1"/>
      </geometry>
    </collision>
    <inertial>
      <mass value="1"/>
      <inertia ixx="0.1" ixy="0.0" ixz="0.0" iyy="0.1" iyz="0.0" izz="0.1"/>
    </inertial>
  </link>
  <link name="tracks">
    <visual>
      <geometry>
        <mesh filename="package://farmbot_description/meshes/visual/tracks.dae"/>
      </geometry>
    </visual>
    <collision>
      <geometry>
        <mesh filename="package://farmbot_description/meshes/visual/tracks.dae"/>
      </geometry>
    </collision>
    <inertial>
      <mass value="10"/>
      <inertia ixx="0.1" ixy="0.0" ixz="0.0" iyy="0.1" iyz="0.0" izz="0.1"/>
    </inertial>
  </link>
  <link name="gantry">
    <visual>
      <geometry>
        <mesh filename="package://farmbot_description/meshes/visual/gantry.dae"/>
      </geometry>
    </visual>
    <collision>
      <geometry>
        <mesh filename="package://farmbot_description/meshes/collision/collision_gantry.stl"/>
      </geometry>
    </collision>
    <inertial>
      <mass value="10"/>
      <inertia ixx="0.1" ixy="0.0" ixz="0.0" iyy="0.1" iyz="0.0" izz="0.1"/>
    </inertial>
  </link>
  <joint name="joint_raisedBed_tracks" type="fixed">
    <parent link="raised_bed"/>
    <child link="tracks"/>
    <origin rpy="0 0 1.57079632679" xyz="0.745 0 0.29"/>
  </joint>
  <!--
  <joint name="joint_gantry_cross_slide" type="fixed">
    <parent link="gantry"/>
    <child link="cross_slide"/>
  </joint>
    <joint name="joint_tracks_gantry" type="fixed">
    <parent link="tracks"/>
    <child link="gantry"/>
  </joint>
    <joint name="joint_raised_bed_tracks" type="fixed">
    <parent link="raised_bed"/>
    <child link="tracks"/>
  </joint>
-->
  <joint name="joint_tracks_gantry" type="prismatic">
    <parent link="tracks"/>
    <child link="gantry"/>
    <axis xyz="0 1 0"/>
    <limit effort="1000.0" lower="-0.38" upper="0" velocity="0.5"/>
    <origin rpy="0 0 1.57079632679" xyz="0 0.745 0.78"/>
  </joint>
  <!--
  <joint name="joint_gantry_cross_slide" type="fixed">
    <parent link="gantry"/>
    <child link="cross_slide"/>
  </joint>
    <joint name="joint_tracks_gantry" type="fixed">
    <parent link="tracks"/>
    <child link="gantry"/>
  </joint>
    <joint name="joint_raised_bed_tracks" type="fixed">
    <parent link="raised_bed"/>
    <child link="tracks"/>
  </joint>
-->
  <joint name="joint_gantry_crossSlide" type="prismatic">
    <parent link="gantry"/>
    <child link="cross_slide"/>
    <axis xyz="1 0 0"/>
    <limit effort="1000.0" lower="-0.38" upper="0" velocity="0.5"/>
    <origin rpy="0 0 0" xyz="0 0 0"/>
  </joint>
  <joint name="joint_cross_slide_z_axis" type="prismatic">
    <parent link="cross_slide"/>
    <child link="z_axis"/>
    <axis xyz="0 0 -1"/>
    <limit effort="1000.0" lower="-0.38" upper="0.35" velocity="0.5"/>
    <origin rpy="0 0 0" xyz="0 0 0"/>
  </joint>
  <!--
  <joint name="joint_gantry_cross_slide" type="fixed">
    <parent link="gantry"/>
    <child link="cross_slide"/>
  </joint>
    <joint name="joint_tracks_gantry" type="fixed">
    <parent link="tracks"/>
    <child link="gantry"/>
  </joint>
    <joint name="joint_raised_bed_tracks" type="fixed">
    <parent link="raised_bed"/>
    <child link="tracks"/>
  </joint>
-->
  <link name="base_link"/>
  <joint name="base_joint" type="fixed">
    <parent link="base_link"/>
    <child link="raised_bed"/>
  </joint>
</robot>

